<?xml version="1" ?>
<robot name="dumpUrdf">
  <!-- <xacro:arg name='upperbody' default='0.5'/> -->
  <!-- <property name='upperbody' value = '0.5'/> -->
	<link name="base" >
		<inertial>
				<origin rpy = "0 0 0" xyz = "0 0 0" />
			 <mass value = "0.0001" />
			<inertia ixx = "0.0001" ixy = "0" ixz = "0" iyy = "0.0001" iyz = "0" izz = "0.0001" />
		</inertial>
	</link>
	<link name="upperbody" >
		<inertial>
			<origin rpy = "0 0 0" xyz = "0.000000 0.250000 0.000000" />
			<mass value = "26.000000" />
		  <inertia ixx = "0.1" ixy = "0" ixz = "0" iyy = "0.1" iyz = "0" izz = "0.1" />
		</inertial>
    <visual>
      <origin rpy = "0 0 0" xyz = "0.000000 0.250000 0.000000" />
      <geometry>
        <box size = '0.25 0.5 0.45'/>
      </geometry>
      <material name = 'maroon'>
        <color rgba = '0.69 0.19 0.38 1' />
      </material>
    </visual>
	</link>
	<joint name="upperbody" type="revolute" >
		<parent link = "base" />
		<child link="upperbody" />
		<limit effort="1000.0" lower="-3.14" upper="3.14" velocity="0.5"/>
		<origin rpy = "0 0 0" xyz = "0.000000 0. 0.000000" />
		<axis xyz = "0.000000 0.000000 1.000000" />
	</joint>
	<link name="neck" >
		<inertial>
				<origin rpy = "0 0 0" xyz = "0.000000 0.050000 0.000000" />
			 <mass value = "6.000000" />
			<inertia ixx = "0.1" ixy = "0" ixz = "0" iyy = "0.1" iyz = "0" izz = "0.1" />
		</inertial>
    <visual>
      <origin rpy = "-1.57 0 0" xyz = "0.000000 0.05 0.000000" />
      <geometry>
        <capsule length="0.02" radius="0.04"/>
      </geometry>
      <material name = 'pink'>
        <color rgba = '1 0.75 0.8 1' />
      </material>
    </visual>    
	</link>
	<joint name="neck" type="revolute" >
		<parent link="upperbody" />
		<child link="neck" />
		<limit effort="1000.0" lower="-3.14" upper="3.14" velocity="0.5"/>
		<origin rpy = "0 0 0" xyz = "0.000000 0.5 0.000000" />
		<axis xyz = "0.000000 0.000000 1.000000" />
	</joint>
	<link name="head" >
		<inertial>
				<origin rpy = "0 0 0" xyz = "0.000000 0.1500000 0.000000" />
			 <mass value = "8.000000" />
			<inertia ixx = "0.1" ixy = "0" ixz = "0" iyy = "0.1" iyz = "0" izz = "0.1" />
		</inertial>
    <visual>
      <origin rpy = "0 0 0" xyz = "0.000000 0.15 0.000000" />
      <geometry>
        <sphere radius="0.15"/>
      </geometry>
      <material name = 'strawberry'>
        <color rgba = '0.53 0.15 0.34 1' />
      </material>
    </visual>  
	</link>
	<joint name="head" type="fixed" >
		<parent link="neck" />
		<child link="head" />
		<origin rpy = "0 0 0" xyz = "0.000000 0.1 0.000000" />
	</joint>
	<link name="nose" >
		<inertial>
				<origin rpy = "0 0 0" xyz = "0.01000000 0.000000 0.000000" />
			 <mass value = "1.000000" />
			<inertia ixx = "0.1" ixy = "0" ixz = "0" iyy = "0.1" iyz = "0" izz = "0.1" />
		</inertial>
    <visual>
      <origin rpy = "0 0 0" xyz = "0.01000000 0 0.000000" />
      <geometry>
        <sphere radius="0.02"/>
      </geometry>
      <material name = 'coralred'>
        <color rgba = '1 0.5 0.31 1' />
      </material>
    </visual>  
	</link>
	<joint name="nose" type="fixed" >
		<parent link="head" />
		<child link="nose" />
		<origin rpy = "0 0 0" xyz = "0.15000000 0.15 0.000000" />
	</joint>
	<link name="right_hip" >
		<inertial>
				<origin rpy = "0 0 0" xyz = "0.000000 -0.25 0.000000" />
			 <mass value = "18.00000" />
			<inertia ixx = "0.1" ixy = "0" ixz = "0" iyy = "0.1" iyz = "0" izz = "0.1" />
		</inertial>
		<visual>
			<origin rpy = "-1.570796 0 0" xyz = "0.000000 -0.25 0.000000" />
			<geometry>
				<capsule length="0.3" radius="0.10000"/> 
			</geometry>
      <material name = 'orangered'>
        <color rgba = '0.98 0.5 0.45 1' />
      </material>
		</visual>
	</link>
	<joint name="right_hip" type="revolute" >
		<parent link="upperbody" />
		<child link="right_hip" />
    	<limit effort="1000.0" lower="-3.14" upper="3.14" velocity="0.5"/>
		<origin rpy = "0 0 0" xyz = "0.000000 0.000000 0.2" />
    	<axis xyz = '0 0 1' />
	</joint>
	<link name="left_hip" >
		<inertial>
				<origin rpy = "0 0 0" xyz = "0.000000 -0.25 0.000000" />
			 <mass value = "18.00000" />
			<inertia ixx = "0.1" ixy = "0" ixz = "0" iyy = "0.1" iyz = "0" izz = "0.1" />
		</inertial>
		<visual>
			<origin rpy = "-1.570796 0 0" xyz = "0.000000 -0.25 0.000000" />
			<geometry>
				<capsule length="0.3" radius="0.10000"/> 
			</geometry>
      <material name = 'potatored'>
        <color rgba = '1 0.39 0.28 1' />
      </material>
		</visual>
	</link>
	<joint name="left_hip" type="revolute" >
		<parent link="upperbody" />
		<child link="left_hip" />
    	<limit effort="1000.0" lower="-3.14" upper="3.14" velocity="0.5"/>
		<origin rpy = "0 0 0" xyz = "0.000000 0.000000 -0.2" />
    	<axis xyz = '0 0 1' />
	</joint>
	<link name="right_knee" >
		<inertial>
				<origin rpy = "0 0 0" xyz = "0.000000 -0.15 0.000000" />
			 <mass value = "14.00000" />
			<inertia ixx = "0.1" ixy = "0" ixz = "0" iyy = "0.1" iyz = "0" izz = "0.1" />
		</inertial>
		<visual>
			<origin rpy = "-1.570796 0 0" xyz = "0.000000 -0.15 0.000000" />
			<geometry>
				<capsule length="0.1" radius="0.10000"/> 
			</geometry>
      <material name = 'banana'>
        <color rgba = '0.89 0.81 0.34 1' />
      </material>
		</visual>
	</link>
	<joint name="right_knee" type="revolute" >
		<parent link="right_hip" />
		<child link="right_knee" />
    	<limit effort="1000.0" lower="-3.14" upper="3.14" velocity="0.5"/>
		<origin rpy = "0 0 0" xyz = "0.000000 -0.5000000 0." />
    	<axis xyz = '0 0 1' />
	</joint>
	<link name="left_knee" >
		<inertial>
				<origin rpy = "0 0 0" xyz = "0.000000 -0.15 0.000000" />
			 <mass value = "14.00000" />
			<inertia ixx = "0.1" ixy = "0" ixz = "0" iyy = "0.1" iyz = "0" izz = "0.1" />
		</inertial>
		<visual>
			<origin rpy = "-1.570796 0 0" xyz = "0.000000 -0.15 0.000000" />
			<geometry>
				<capsule length="0.1" radius="0.10000"/> 
			</geometry>
      <material name = 'cadmium'>
        <color rgba = '1 0.6 0.07 1' />
      </material>
		</visual>
	</link>
	<joint name="left_knee" type="revolute" >
		<parent link="left_hip" />
		<child link="left_knee" />
    	<limit effort="1000.0" lower="-3.14" upper="3.14" velocity="0.5"/>
		<origin rpy = "0 0 0" xyz = "0.000000 -0.5000000 0." />
    	<axis xyz = '0 0 1' />
	</joint>
	<link name="right_feet" >
		<inertial>
				<origin rpy = "0 0 0" xyz = "0.000000 -0.025 0.000000" />
			 <mass value = "6.00000" />
			<inertia ixx = "0.1" ixy = "0" ixz = "0" iyy = "0.1" iyz = "0" izz = "0.1" />
		</inertial>
		<visual>
			<origin rpy = "0 0 0" xyz = "0.000000 -0.025 0.000000" />
			<geometry>
				<box size='0.2 0.05 0.2'/> 
			</geometry>
      <material name = 'dougello'>
        <color rgba = '0.92 0.56 0.33 1' />
      </material>
		</visual>
	</link>
	<joint name="right_feet" type="fixed" >
		<parent link="right_knee" />
		<child link="right_feet" />
		<origin rpy = "0 0 0" xyz = "0.000000 -0.3000000 0." />
	</joint>
	<link name="left_feet" >
		<inertial>
				<origin rpy = "0 0 0" xyz = "0.000000 -0.025 0.000000" />
			 <mass value = "14.00000" />
			<inertia ixx = "0.1" ixy = "0" ixz = "0" iyy = "0.1" iyz = "0" izz = "0.1" />
		</inertial>
		<visual>
			<origin rpy = "0 0 0" xyz = "0.000000 -0.025 0.000000" />
			<geometry>
				<box size='0.2 0.05 0.2'/> 
			</geometry>
      <material name = 'forumgold'>
        <color rgba = '1 0.89 0.52 1' />
      </material>
		</visual>
	</link>
	<joint name="left_feet" type="fixed" >
		<parent link="left_knee" />
		<child link="left_feet" />
		<origin rpy = "0 0 0" xyz = "0.000000 -0.3000000 0." />
	</joint>
	<link name="right_shoulder" >
		<inertial>
				<origin rpy = "0 0 0" xyz = "0.000000 -0.18 0.000000" />
			 <mass value = "10.00000" />
			<inertia ixx = "0.1" ixy = "0" ixz = "0" iyy = "0.1" iyz = "0" izz = "0.1" />
		</inertial>
		<visual>
			<origin rpy = "-1.570796 0 0" xyz = "0.000000 -0.18 0.000000" />
			<geometry>
				<capsule length="0.24" radius="0.060000"/> 
			</geometry>
      <material name = 'lightpurple'>
        <color rgba = '0.85 0.44 0.84 1' />
      </material>
		</visual>
	</link>
	<joint name="right_shoulder" type="revolute" >
		<parent link="neck" />
		<child link="right_shoulder" />
    	<limit effort="1000.0" lower="-3.14" upper="3.14" velocity="0.5"/>
		<origin rpy = "0 0 0" xyz = "0.000000 0.000000 0.35" />
    <axis xyz = '0 0 1' />
	</joint>
	<link name="left_shoulder" >
		<inertial>
				<origin rpy = "0 0 0" xyz = "0.000000 -0.18 0.000000" />
			 <mass value = "14.00000" />
			<inertia ixx = "0.1" ixy = "0" ixz = "0" iyy = "0.1" iyz = "0" izz = "0.1" />
		</inertial>
		<visual>
			<origin rpy = "-1.570796 0 0" xyz = "0.000000 -0.18 0.000000" />
			<geometry>
				<capsule length="0.24" radius="0.060000"/> 
			</geometry>
      <material name = 'plumpurple'>
        <color rgba = '0.87 0.63 0.87 1' />
      </material>
		</visual>
	</link>
	<joint name="left_shoulder" type="revolute" >
		<parent link="neck" />
		<child link="left_shoulder" />
    	<limit effort="1000.0" lower="-3.14" upper="3.14" velocity="0.5"/>
		<origin rpy = "0 0 0" xyz = "0.000000 0.000000 -0.35" />
    <axis xyz = '0 0 1' />
	</joint>
	<link name="right_elbow" >
		<inertial>
				<origin rpy = "0 0 0" xyz = "0.000000 -0.12 0.000000" />
			 <mass value = "8.00000" />
			<inertia ixx = "0.1" ixy = "0" ixz = "0" iyy = "0.1" iyz = "0" izz = "0.1" />
		</inertial>
		<visual>
			<origin rpy = "-1.570796 0 0" xyz = "0.000000 -0.12 0.000000" />
			<geometry>
				<capsule length="0.12" radius="0.060000"/> 
			</geometry>
      <material name = 'jadegreen'>
        <color rgba = '0.0 0.79 0.34 1' />
      </material>
		</visual>
	</link>
	<joint name="right_elbow" type="revolute" >
		<parent link="right_shoulder" />
		<child link="right_elbow" />
    	<limit effort="1000.0" lower="-3.14" upper="3.14" velocity="0.5"/>
		<origin rpy = "0 0 0" xyz = "0.000000 -0.36 0.0" />
    	<axis xyz = '0 0 1' />
	</joint>
	<link name="left_elbow" >
		<inertial>
				<origin rpy = "0 0 0" xyz = "0.000000 -0.12 0.000000" />
			 <mass value = "8.00000" />
			<inertia ixx = "0.1" ixy = "0" ixz = "0" iyy = "0.1" iyz = "0" izz = "0.1" />
		</inertial>
		<visual>
			<origin rpy = "-1.570796 0 0" xyz = "0.000000 -0.12 0.000000" />
			<geometry>
				<capsule length="0.12" radius="0.060000"/> 
			</geometry>
      <material name = 'forestgreen'>
        <color rgba = '0.13 0.55 0.13 1' />
      </material>
		</visual>
	</link>
	<joint name="left_elbow" type="revolute" >
		<parent link="left_shoulder" />
		<child link="left_elbow" />
    	<limit effort="1000.0" lower="-3.14" upper="3.14" velocity="0.5"/>
		<origin rpy = "0 0 0" xyz = "0.000000 -0.36 0.0" />
    	<axis xyz = '0 0 1' />
	</joint>
	<link name="right_hand" >
		<inertial>
				<origin rpy = "0 0 0" xyz = "0.000000 -0.025 0.000000" />
			 <mass value = "2.00000" />
			<inertia ixx = "0.1" ixy = "0" ixz = "0" iyy = "0.1" iyz = "0" izz = "0.1" />
		</inertial>
		<visual>
			<origin rpy = "0 0 0" xyz = "0.000000 -0.025 0.000000" />
			<geometry>
				<box size='0.07 0.05 0.07'/> 
			</geometry>
      <material name = 'vividgreen'>
        <color rgba = '0.5 1.0 0.83 1' />
      </material>
		</visual>
	</link>
	<joint name="right_hand" type="fixed" >
		<parent link="right_elbow" />
		<child link="right_hand" />
		<origin rpy = "0 0 0" xyz = "0.000000 -0.24 0.0" />
	</joint>
	<link name="left_hand" >
		<inertial>
				<origin rpy = "0 0 0" xyz = "0.000000 -0.025 0.000000" />
			 <mass value = "2.00000" />
			<inertia ixx = "0.1" ixy = "0" ixz = "0" iyy = "0.1" iyz = "0" izz = "0.1" />
		</inertial>
		<visual>
			<origin rpy = "0 0 0" xyz = "0.000000 -0.025 0.000000" />
			<geometry>
				<box size='0.07 0.05 0.07'/> 
			</geometry>
      <material name = 'turquoise'>
        <color rgba = '0.25 0.88 0.82 1' />
      </material>
		</visual>
	</link>
	<joint name="left_hand" type="fixed" >
		<parent link="left_elbow" />
		<child link="left_hand" />
		<origin rpy = "0 0 0" xyz = "0.000000 -0.24 0.0" />
	</joint>
</robot>